<sdf version='1.4'>
  <world name='default'>
    <light name='sun' type='directional'>
      <cast_shadows>1</cast_shadows>
      <pose>0 0 10 0 -0 0</pose>
      <diffuse>0.8 0.8 0.8 1</diffuse>
      <specular>0.2 0.2 0.2 1</specular>
      <attenuation>
        <range>1000</range>
        <constant>0.9</constant>
        <linear>0.01</linear>
        <quadratic>0.001</quadratic>
      </attenuation>
      <direction>-0.5 0.1 -0.9</direction>
    </light>
    <model name='ground_plane'>
      <static>1</static>
      <link name='link'>
        <collision name='collision'>
          <geometry>
            <plane>
              <normal>0 0 1</normal>
              <size>100 100</size>
            </plane>
          </geometry>
          <surface>
            <friction>
              <ode>
                <mu>100</mu>
                <mu2>50</mu2>
              </ode>
            </friction>
            <bounce/>
            <contact>
              <ode/>
            </contact>
          </surface>
          <max_contacts>10</max_contacts>
        </collision>
        <visual name='visual'>
          <cast_shadows>0</cast_shadows>
          <geometry>
            <plane>
              <normal>0 0 1</normal>
              <size>100 100</size>
            </plane>
          </geometry>
          <material>
            <script>
              <uri>file://media/materials/scripts/gazebo.material</uri>
              <name>Gazebo/Grey</name>
            </script>
          </material>
        </visual>
        <velocity_decay>
          <linear>0</linear>
          <angular>0</angular>
        </velocity_decay>
        <self_collide>0</self_collide>
        <kinematic>0</kinematic>
        <gravity>1</gravity>
      </link>
    </model>
    <physics type='ode'>
      <max_step_size>0.001</max_step_size>
      <real_time_factor>1</real_time_factor>
      <real_time_update_rate>1000</real_time_update_rate>
      <gravity>0 0 -9.8</gravity>
    </physics>
    <scene>
      <ambient>0.4 0.4 0.4 1</ambient>
      <background>0.7 0.7 0.7 1</background>
      <shadows>1</shadows>
    </scene>
    <spherical_coordinates>
      <surface_model>EARTH_WGS84</surface_model>
      <latitude_deg>0</latitude_deg>
      <longitude_deg>0</longitude_deg>
      <elevation>0</elevation>
      <heading_deg>0</heading_deg>
    </spherical_coordinates>
    <state world_name='default'>
      <sim_time>649 654000000</sim_time>
      <real_time>432 488977665</real_time>
      <wall_time>1480931016 142917735</wall_time>
      <model name='firebird'>
        <pose>0.000337 -5e-06 -0.005027 -8.40267e-24 -0.000368 -0.000123</pose>
        <link name='base_link'>
          <pose>0.000337 -5e-06 -0.005027 -8.40267e-24 -0.000368 -0.000123</pose>
          <velocity>8.7e-05 -1e-06 -0.006831 -3.7e-05 -0.017386 1.62617e-23</velocity>
          <acceleration>0 0 0 0 -0 0</acceleration>
          <wrench>0 0 0 0 -0 0</wrench>
        </link>
        <link name='caster_front_link'>
          <pose>0.070331 -1.3e-05 0.012142 -1.54377 -0.000368 -0.000123</pose>
          <velocity>-0.000212 0 -0.006236 5.9e-05 -0.017377 -1.4664e-22</velocity>
          <acceleration>0 0 0 0 -0 0</acceleration>
          <wrench>0 0 0 0 -0 0</wrench>
        </link>
        <link name='left_wheel'>
          <pose>-0.039711 -0.115 0.032458 -1.93207e-22 0.009553 -0.000123</pose>
          <velocity>-0.000565 1e-06 -0.007478 -3.6e-05 -0.017386 -1.01086e-23</velocity>
          <acceleration>0 0 0 0 -0 0</acceleration>
          <wrench>0 0 0 0 -0 0</wrench>
        </link>
        <link name='right_wheel'>
          <pose>-0.039682 0.115 0.032458 3.78973e-23 0.010424 -0.000123</pose>
          <velocity>-0.000565 1e-06 -0.007487 -2.7e-05 -0.017386 1e-06</velocity>
          <acceleration>0 0 0 0 -0 0</acceleration>
          <wrench>0 0 0 0 -0 0</wrench>
        </link>
      </model>
      <model name='ground_plane'>
        <pose>0 0 0 0 -0 0</pose>
        <link name='link'>
          <pose>0 0 0 0 -0 0</pose>
          <velocity>0 0 0 0 -0 0</velocity>
          <acceleration>0 0 0 0 -0 0</acceleration>
          <wrench>0 0 0 0 -0 0</wrench>
        </link>
      </model>
      <model name='task_1'>
        <pose>0 -0 0 0 -0 0</pose>
        <link name='Wall_16'>
          <pose>-6 0.1 0 0 0 -1.5708</pose>
          <velocity>0 0 0 0 -0 0</velocity>
          <acceleration>0 0 0 0 -0 0</acceleration>
          <wrench>0 0 0 0 -0 0</wrench>
        </link>
        <link name='Wall_18'>
          <pose>6 -0 0 0 -0 1.5708</pose>
          <velocity>0 0 0 0 -0 0</velocity>
          <acceleration>0 0 0 0 -0 0</acceleration>
          <wrench>0 0 0 0 -0 0</wrench>
        </link>
        <link name='Wall_23'>
          <pose>-0.050497 6.00163 0 0 -0 0</pose>
          <velocity>0 0 0 0 -0 0</velocity>
          <acceleration>0 0 0 0 -0 0</acceleration>
          <wrench>0 0 0 0 -0 0</wrench>
        </link>
        <link name='Wall_25'>
          <pose>0 -6 0 0 -0 0</pose>
          <velocity>0 0 0 0 -0 0</velocity>
          <acceleration>0 0 0 0 -0 0</acceleration>
          <wrench>0 0 0 0 -0 0</wrench>
        </link>
      </model>
      <model name='unit_box_2_0'>
        <pose>1 -4 0.5 0 -0 0</pose>
        <link name='link'>
          <pose>1 -4 0.5 0 -0 0</pose>
          <velocity>0 0 0 0 -0 0</velocity>
          <acceleration>0 0 0 0 -0 0</acceleration>
          <wrench>0 0 0 0 -0 0</wrench>
        </link>
      </model>
      <model name='unit_box_3_0'>
        <pose>-3 3 0.5 0 -0 0</pose>
        <link name='link'>
          <pose>-3 3 0.5 0 -0 0</pose>
          <velocity>0 0 0 0 -0 0</velocity>
          <acceleration>0 0 0 0 -0 0</acceleration>
          <wrench>0 0 0 0 -0 0</wrench>
        </link>
      </model>
      <model name='unit_cylinder_2'>
        <pose>3 4 0.499992 -1e-06 -0 0</pose>
        <link name='link'>
          <pose>3 4 0.499992 -1e-06 -0 0</pose>
          <velocity>0 0 0 0 -0 0</velocity>
          <acceleration>0 0 0 0 -0 0</acceleration>
          <wrench>0 0 0 0 -0 0</wrench>
        </link>
      </model>
      <model name='unit_sphere_1'>
        <pose>3 0 0.5 0 -0 0</pose>
        <link name='link'>
          <pose>3 0 0.5 0 -0 0</pose>
          <velocity>0 0 0 0 -0 0</velocity>
          <acceleration>0 0 0 0 -0 0</acceleration>
          <wrench>0 0 0 0 -0 0</wrench>
        </link>
      </model>
      <model name='unit_sphere_2'>
        <pose>-5 -2 0.5 0 -0 0</pose>
        <link name='link'>
          <pose>-5 -2 0.5 0 -0 0</pose>
          <velocity>0 0 0 0 -0 0</velocity>
          <acceleration>0 0 0 0 -0 0</acceleration>
          <wrench>0 0 0 0 -0 0</wrench>
        </link>
      </model>
    </state>
    <gui fullscreen='0'>
      <camera name='user_camera'>
        <pose>-4.85168 0.075519 13.0596 -5.1269e-19 1.22703 -0.005489</pose>
        <view_controller>orbit</view_controller>
      </camera>
    </gui>
    <model name='firebird'>
      <link name='base_link'>
        <pose>0 0 0 0 -0 0</pose>
        <inertial>
          <pose>0.00301435 0 0.0010688 0 -0 0</pose>
          <mass>1.045</mass>
          <inertia>
            <ixx>0.0294015</ixx>
            <ixy>0</ixy>
            <ixz>-7.48163e-05</ixz>
            <iyy>0.0296125</iyy>
            <iyz>0</iyz>
            <izz>0.058461</izz>
          </inertia>
        </inertial>
        <collision name='base_link_collision'>
          <pose>0 0 0.0375 0 -0 0</pose>
          <geometry>
            <box>
              <size>0.2 0.2 0.01</size>
            </box>
          </geometry>
          <surface>
            <contact>
              <ode/>
            </contact>
            <friction>
              <ode/>
            </friction>
            <bounce/>
          </surface>
          <max_contacts>10</max_contacts>
        </collision>
        <collision name='base_link_collision_caster_link'>
          <pose>0.07 0 0.02482 0 -0 0</pose>
          <geometry>
            <cylinder>
              <length>0.01536</length>
              <radius>0.01214</radius>
            </cylinder>
          </geometry>
          <surface>
            <contact>
              <ode/>
            </contact>
            <friction>
              <ode/>
            </friction>
            <bounce/>
          </surface>
          <surface>
            <contact>
              <ode/>
            </contact>
            <friction>
              <ode/>
            </friction>
          </surface>
          <max_contacts>10</max_contacts>
        </collision>
        <visual name='base_link_visual'>
          <pose>0 0 0.0375 0 -0 0</pose>
          <geometry>
            <box>
              <size>0.2 0.2 0.01</size>
            </box>
          </geometry>
          <material>
            <script>
              <name>Gazebo/Green</name>
              <uri>__default__</uri>
            </script>
          </material>
        </visual>
        <visual name='base_link_visual_caster_link'>
          <pose>0.07 0 0.02482 0 -0 0</pose>
          <geometry>
            <cylinder>
              <length>0.01536</length>
              <radius>0.01214</radius>
            </cylinder>
          </geometry>
        </visual>
        <visual name='base_link_visual_sharp1'>
          <pose>0.07 0 0.050835 0 -0 0</pose>
          <geometry>
            <box>
              <size>0.03333 0.03333 0.01667</size>
            </box>
          </geometry>
          <material>
            <script>
              <name>Gazebo/Blue</name>
              <uri>__default__</uri>
            </script>
          </material>
        </visual>
        <velocity_decay>
          <linear>0</linear>
          <angular>0</angular>
        </velocity_decay>
        <velocity_decay>
          <linear>0</linear>
          <angular>0</angular>
        </velocity_decay>
        <gravity>1</gravity>
        <velocity_decay>
          <linear>0</linear>
          <angular>0</angular>
        </velocity_decay>
        <self_collide>0</self_collide>
        <sensor name='sharp_sensor1' type='ray'>
          <visualize>1</visualize>
          <update_rate>100</update_rate>
          <ray>
            <scan>
              <horizontal>
                <samples>700</samples>
                <resolution>1</resolution>
                <min_angle>-2.0598</min_angle>
                <max_angle>2.0598</max_angle>
              </horizontal>
            </scan>
            <range>
              <min>0.1</min>
              <max>30</max>
              <resolution>0.01</resolution>
            </range>
          </ray>
          <plugin name='gazebo_ros_head_hokuyo_controller' filename='libgazebo_ros_laser.so'>
            <topicName>/scan1</topicName>
            <frameName>sharp1</frameName>
            <robotNamespace>/</robotNamespace>
          </plugin>
          <pose>0.07 0 0.050835 0 -0 0</pose>
        </sensor>
        <kinematic>0</kinematic>
      </link>
      <link name='caster_front_link'>
        <pose>0.07 0 0.01714 -1.5708 0 0</pose>
        <inertial>
          <pose>0 0 0 0 -0 0</pose>
          <mass>0.02</mass>
          <inertia>
            <ixx>0.001</ixx>
            <ixy>0</ixy>
            <ixz>0</ixz>
            <iyy>0.001</iyy>
            <iyz>0</iyz>
            <izz>0.001</izz>
          </inertia>
        </inertial>
        <collision name='caster_front_link_collision'>
          <pose>0 0 0 1.5708 -0 0</pose>
          <geometry>
            <sphere>
              <radius>0.01214</radius>
            </sphere>
          </geometry>
          <surface>
            <contact>
              <ode/>
            </contact>
            <friction>
              <ode/>
            </friction>
            <bounce/>
          </surface>
          <max_contacts>10</max_contacts>
        </collision>
        <visual name='caster_front_link_visual'>
          <pose>0 0 0 1.5708 -0 0</pose>
          <geometry>
            <sphere>
              <radius>0.01214</radius>
            </sphere>
          </geometry>
        </visual>
        <gravity>1</gravity>
        <velocity_decay>
          <linear>0</linear>
          <angular>0</angular>
        </velocity_decay>
        <self_collide>0</self_collide>
        <kinematic>0</kinematic>
      </link>
      <joint name='caster_front_joint' type='revolute'>
        <child>caster_front_link</child>
        <parent>base_link</parent>
        <axis>
          <xyz>1 0 0</xyz>
          <limit>
            <lower>-1e+16</lower>
            <upper>1e+16</upper>
          </limit>
          <dynamics/>
        </axis>
      </joint>
      <link name='left_wheel'>
        <pose>-0.04002 -0.115 0.0375 0 -0 0</pose>
        <inertial>
          <pose>0 0 0 0 -0 0</pose>
          <mass>0.045</mass>
          <inertia>
            <ixx>0.00108333</ixx>
            <ixy>0</ixy>
            <ixz>0</ixz>
            <iyy>0.00108333</iyy>
            <iyz>0</iyz>
            <izz>0.002</izz>
          </inertia>
        </inertial>
        <collision name='left_wheel_collision'>
          <pose>0 0 0 1.5708 -0 0</pose>
          <geometry>
            <cylinder>
              <length>0.03</length>
              <radius>0.0325</radius>
            </cylinder>
          </geometry>
          <surface>
            <contact>
              <ode>
                <kp>100000</kp>
                <kd>1</kd>
              </ode>
            </contact>
            <friction>
              <ode>
                <mu>1</mu>
                <mu2>1</mu2>
                <fdir1>1 0 0</fdir1>
              </ode>
            </friction>
            <bounce/>
          </surface>
          <max_contacts>10</max_contacts>
        </collision>
        <visual name='left_wheel_visual'>
          <pose>0 0 0 1.5708 -0 0</pose>
          <geometry>
            <cylinder>
              <length>0.03</length>
              <radius>0.0325</radius>
            </cylinder>
          </geometry>
          <material>
            <script>
              <name>Gazebo/Grey</name>
              <uri>__default__</uri>
            </script>
          </material>
        </visual>
        <gravity>1</gravity>
        <velocity_decay>
          <linear>0</linear>
          <angular>0</angular>
        </velocity_decay>
        <self_collide>0</self_collide>
        <kinematic>0</kinematic>
      </link>
      <joint name='left_wheel_joint' type='revolute'>
        <child>left_wheel</child>
        <parent>base_link</parent>
        <axis>
          <xyz>0 1 0</xyz>
          <limit>
            <lower>-1e+16</lower>
            <upper>1e+16</upper>
          </limit>
          <dynamics/>
        </axis>
      </joint>
      <link name='right_wheel'>
        <pose>-0.04002 0.115 0.0375 0 -0 0</pose>
        <inertial>
          <pose>0 0 0 0 -0 0</pose>
          <mass>0.045</mass>
          <inertia>
            <ixx>0.00108333</ixx>
            <ixy>0</ixy>
            <ixz>0</ixz>
            <iyy>0.00108333</iyy>
            <iyz>0</iyz>
            <izz>0.002</izz>
          </inertia>
        </inertial>
        <collision name='right_wheel_collision'>
          <pose>0 0 0 1.5708 -0 0</pose>
          <geometry>
            <cylinder>
              <length>0.03</length>
              <radius>0.0325</radius>
            </cylinder>
          </geometry>
          <surface>
            <contact>
              <ode>
                <kp>100000</kp>
                <kd>1</kd>
              </ode>
            </contact>
            <friction>
              <ode>
                <mu>1</mu>
                <mu2>1</mu2>
                <fdir1>1 0 0</fdir1>
              </ode>
            </friction>
            <bounce/>
          </surface>
          <max_contacts>10</max_contacts>
        </collision>
        <visual name='right_wheel_visual'>
          <pose>0 0 0 1.5708 -0 0</pose>
          <geometry>
            <cylinder>
              <length>0.03</length>
              <radius>0.0325</radius>
            </cylinder>
          </geometry>
          <material>
            <script>
              <name>Gazebo/Grey</name>
              <uri>__default__</uri>
            </script>
          </material>
        </visual>
        <gravity>1</gravity>
        <velocity_decay>
          <linear>0</linear>
          <angular>0</angular>
        </velocity_decay>
        <self_collide>0</self_collide>
        <kinematic>0</kinematic>
      </link>
      <joint name='right_wheel_joint' type='revolute'>
        <child>right_wheel</child>
        <parent>base_link</parent>
        <axis>
          <xyz>0 1 0</xyz>
          <limit>
            <lower>-1e+16</lower>
            <upper>1e+16</upper>
          </limit>
          <dynamics/>
        </axis>
      </joint>
      <static>0</static>
      <plugin name='differential_drive_controller_front' filename='libgazebo_ros_diff_drive.so'>
        <rosDebugLevel>Debug</rosDebugLevel>
        <publishWheelTF>True</publishWheelTF>
        <publishTf>1</publishTf>
        <publishWheelJointState>true</publishWheelJointState>
        <alwaysOn>true</alwaysOn>
        <updateRate>100.0</updateRate>
        <leftJoint>left_wheel_joint</leftJoint>
        <rightJoint>right_wheel_joint</rightJoint>
        <wheelSeparation>0.3</wheelSeparation>
        <wheelDiameter>0.065</wheelDiameter>
        <broadcastTF>1</broadcastTF>
        <wheelTorque>30</wheelTorque>
        <wheelAcceleration>1.8</wheelAcceleration>
        <commandTopic>cmd_vel</commandTopic>
        <odometryFrame>odom</odometryFrame>
        <odometryTopic>odom</odometryTopic>
        <robotBaseFrame>base_link</robotBaseFrame>
        <robotNamespace>/</robotNamespace>
      </plugin>
      <pose>0 0 0 0 -0 0</pose>
    </model>
    <model name='task_1'>
      <static>1</static>
      <link name='Wall_16'>
        <collision name='Wall_16_Collision'>
          <geometry>
            <box>
              <size>12 0.2 1</size>
            </box>
          </geometry>
          <pose>0 0 0.5 0 -0 0</pose>
          <max_contacts>10</max_contacts>
          <surface>
            <bounce/>
            <friction>
              <ode/>
            </friction>
            <contact>
              <ode/>
            </contact>
          </surface>
        </collision>
        <visual name='Wall_16_Visual'>
          <pose>0 0 0.5 0 -0 0</pose>
          <geometry>
            <box>
              <size>12 0.2 1</size>
            </box>
          </geometry>
          <material>
            <script>
              <uri>file://media/materials/scripts/gazebo.material</uri>
              <name>Gazebo/Grey</name>
            </script>
          </material>
        </visual>
        <velocity_decay>
          <linear>0</linear>
          <angular>0</angular>
        </velocity_decay>
        <pose>-6 0.1 0 0 0 -1.5708</pose>
        <self_collide>0</self_collide>
        <kinematic>0</kinematic>
        <gravity>1</gravity>
      </link>
      <link name='Wall_18'>
        <collision name='Wall_18_Collision'>
          <geometry>
            <box>
              <size>12.2 0.2 1</size>
            </box>
          </geometry>
          <pose>0 0 0.5 0 -0 0</pose>
          <max_contacts>10</max_contacts>
          <surface>
            <bounce/>
            <friction>
              <ode/>
            </friction>
            <contact>
              <ode/>
            </contact>
          </surface>
        </collision>
        <visual name='Wall_18_Visual'>
          <pose>0 0 0.5 0 -0 0</pose>
          <geometry>
            <box>
              <size>12.2 0.2 1</size>
            </box>
          </geometry>
          <material>
            <script>
              <uri>file://media/materials/scripts/gazebo.material</uri>
              <name>Gazebo/Grey</name>
            </script>
          </material>
        </visual>
        <velocity_decay>
          <linear>0</linear>
          <angular>0</angular>
        </velocity_decay>
        <pose>6 0 0 0 -0 1.5708</pose>
        <self_collide>0</self_collide>
        <kinematic>0</kinematic>
        <gravity>1</gravity>
      </link>
      <link name='Wall_23'>
        <collision name='Wall_23_Collision'>
          <geometry>
            <box>
              <size>12 0.2 1</size>
            </box>
          </geometry>
          <pose>0 0 0.5 0 -0 0</pose>
          <max_contacts>10</max_contacts>
          <surface>
            <bounce/>
            <friction>
              <ode/>
            </friction>
            <contact>
              <ode/>
            </contact>
          </surface>
        </collision>
        <visual name='Wall_23_Visual'>
          <pose>0 0 0.5 0 -0 0</pose>
          <geometry>
            <box>
              <size>12 0.2 1</size>
            </box>
          </geometry>
          <material>
            <script>
              <uri>file://media/materials/scripts/gazebo.material</uri>
              <name>Gazebo/Grey</name>
            </script>
          </material>
        </visual>
        <velocity_decay>
          <linear>0</linear>
          <angular>0</angular>
        </velocity_decay>
        <pose>-0.050497 6.00163 0 0 -0 0</pose>
        <self_collide>0</self_collide>
        <kinematic>0</kinematic>
        <gravity>1</gravity>
      </link>
      <link name='Wall_25'>
        <collision name='Wall_25_Collision'>
          <geometry>
            <box>
              <size>12.2 0.2 1</size>
            </box>
          </geometry>
          <pose>0 0 0.5 0 -0 0</pose>
          <max_contacts>10</max_contacts>
          <surface>
            <bounce/>
            <friction>
              <ode/>
            </friction>
            <contact>
              <ode/>
            </contact>
          </surface>
        </collision>
        <visual name='Wall_25_Visual'>
          <pose>0 0 0.5 0 -0 0</pose>
          <geometry>
            <box>
              <size>12.2 0.2 1</size>
            </box>
          </geometry>
          <material>
            <script>
              <uri>file://media/materials/scripts/gazebo.material</uri>
              <name>Gazebo/Grey</name>
            </script>
          </material>
        </visual>
        <velocity_decay>
          <linear>0</linear>
          <angular>0</angular>
        </velocity_decay>
        <pose>0 -6 0 0 -0 0</pose>
        <self_collide>0</self_collide>
        <kinematic>0</kinematic>
        <gravity>1</gravity>
      </link>
      <static>1</static>
      <pose>0 0 0 0 -0 0</pose>
    </model>
    <model name='unit_cylinder_2'>
      <pose>3 4 0.5 0 -0 0</pose>
      <link name='link'>
        <inertial>
          <mass>1</mass>
          <inertia>
            <ixx>1</ixx>
            <ixy>0</ixy>
            <ixz>0</ixz>
            <iyy>1</iyy>
            <iyz>0</iyz>
            <izz>1</izz>
          </inertia>
        </inertial>
        <collision name='collision'>
          <geometry>
            <cylinder>
              <radius>0.5</radius>
              <length>1</length>
            </cylinder>
          </geometry>
          <max_contacts>10</max_contacts>
          <surface>
            <bounce/>
            <friction>
              <ode/>
            </friction>
            <contact>
              <ode/>
            </contact>
          </surface>
        </collision>
        <visual name='visual'>
          <geometry>
            <cylinder>
              <radius>0.5</radius>
              <length>1</length>
            </cylinder>
          </geometry>
          <material>
            <script>
              <uri>file://media/materials/scripts/gazebo.material</uri>
              <name>Gazebo/Grey</name>
            </script>
          </material>
        </visual>
        <velocity_decay>
          <linear>0</linear>
          <angular>0</angular>
        </velocity_decay>
        <self_collide>0</self_collide>
        <kinematic>0</kinematic>
        <gravity>1</gravity>
      </link>
      <static>0</static>
    </model>
    <model name='unit_sphere_1'>
      <pose>3 0 0.5 0 -0 0</pose>
      <link name='link'>
        <inertial>
          <mass>1</mass>
          <inertia>
            <ixx>1</ixx>
            <ixy>0</ixy>
            <ixz>0</ixz>
            <iyy>1</iyy>
            <iyz>0</iyz>
            <izz>1</izz>
          </inertia>
        </inertial>
        <collision name='collision'>
          <geometry>
            <sphere>
              <radius>0.5</radius>
            </sphere>
          </geometry>
          <max_contacts>10</max_contacts>
          <surface>
            <bounce/>
            <friction>
              <ode/>
            </friction>
            <contact>
              <ode/>
            </contact>
          </surface>
        </collision>
        <visual name='visual'>
          <geometry>
            <sphere>
              <radius>0.5</radius>
            </sphere>
          </geometry>
          <material>
            <script>
              <uri>file://media/materials/scripts/gazebo.material</uri>
              <name>Gazebo/Grey</name>
            </script>
          </material>
        </visual>
        <velocity_decay>
          <linear>0</linear>
          <angular>0</angular>
        </velocity_decay>
        <self_collide>0</self_collide>
        <kinematic>0</kinematic>
        <gravity>1</gravity>
      </link>
      <static>0</static>
    </model>
    <model name='unit_box_2_0'>
      <pose>1 -4 0.5 0 -0 0</pose>
      <link name='link'>
        <inertial>
          <mass>1</mass>
          <inertia>
            <ixx>1</ixx>
            <ixy>0</ixy>
            <ixz>0</ixz>
            <iyy>1</iyy>
            <iyz>0</iyz>
            <izz>1</izz>
          </inertia>
        </inertial>
        <collision name='collision'>
          <geometry>
            <box>
              <size>1 1 1</size>
            </box>
          </geometry>
          <max_contacts>10</max_contacts>
          <surface>
            <bounce/>
            <friction>
              <ode/>
            </friction>
            <contact>
              <ode/>
            </contact>
          </surface>
        </collision>
        <visual name='visual'>
          <geometry>
            <box>
              <size>1 1 1</size>
            </box>
          </geometry>
          <material>
            <script>
              <uri>file://media/materials/scripts/gazebo.material</uri>
              <name>Gazebo/Grey</name>
            </script>
          </material>
        </visual>
        <velocity_decay>
          <linear>0</linear>
          <angular>0</angular>
        </velocity_decay>
        <self_collide>0</self_collide>
        <kinematic>0</kinematic>
        <gravity>1</gravity>
      </link>
      <static>0</static>
    </model>
    <model name='unit_sphere_2'>
      <pose>-5 -2 0.5 0 -0 0</pose>
      <link name='link'>
        <inertial>
          <mass>1</mass>
          <inertia>
            <ixx>1</ixx>
            <ixy>0</ixy>
            <ixz>0</ixz>
            <iyy>1</iyy>
            <iyz>0</iyz>
            <izz>1</izz>
          </inertia>
        </inertial>
        <collision name='collision'>
          <geometry>
            <sphere>
              <radius>0.5</radius>
            </sphere>
          </geometry>
          <max_contacts>10</max_contacts>
          <surface>
            <bounce/>
            <friction>
              <ode/>
            </friction>
            <contact>
              <ode/>
            </contact>
          </surface>
        </collision>
        <visual name='visual'>
          <geometry>
            <sphere>
              <radius>0.5</radius>
            </sphere>
          </geometry>
          <material>
            <script>
              <uri>file://media/materials/scripts/gazebo.material</uri>
              <name>Gazebo/Grey</name>
            </script>
          </material>
        </visual>
        <velocity_decay>
          <linear>0</linear>
          <angular>0</angular>
        </velocity_decay>
        <self_collide>0</self_collide>
        <kinematic>0</kinematic>
        <gravity>1</gravity>
      </link>
      <static>0</static>
    </model>
    <model name='unit_box_3_0'>
      <pose>-3 3 0.5 0 -0 0</pose>
      <link name='link'>
        <inertial>
          <mass>1</mass>
          <inertia>
            <ixx>1</ixx>
            <ixy>0</ixy>
            <ixz>0</ixz>
            <iyy>1</iyy>
            <iyz>0</iyz>
            <izz>1</izz>
          </inertia>
        </inertial>
        <collision name='collision'>
          <geometry>
            <box>
              <size>1 1 1</size>
            </box>
          </geometry>
          <max_contacts>10</max_contacts>
          <surface>
            <bounce/>
            <friction>
              <ode/>
            </friction>
            <contact>
              <ode/>
            </contact>
          </surface>
        </collision>
        <visual name='visual'>
          <geometry>
            <box>
              <size>1 1 1</size>
            </box>
          </geometry>
          <material>
            <script>
              <uri>file://media/materials/scripts/gazebo.material</uri>
              <name>Gazebo/Grey</name>
            </script>
          </material>
        </visual>
        <velocity_decay>
          <linear>0</linear>
          <angular>0</angular>
        </velocity_decay>
        <self_collide>0</self_collide>
        <kinematic>0</kinematic>
        <gravity>1</gravity>
      </link>
      <static>0</static>
    </model>
  </world>
</sdf>
